47장 에러 처리

# 에러 처리

## 에러 처리의 필요성

언제나 에러는 발생할 수 있음. 에러나 예외를 대처하지 않고 방치하면 프로그램은 강제 종료됨

## try catch finally

try catch finally 3개의 블록으로 구성됨

finally 블록은 생략 가능함

```javascript
try {
  // 에러가 발생할 수 있는 코드
} catch (error) {
  // 에러 처리
} finally {
  // 에러 발생 여부와 상관없이 항상 실행
}

// try catch finally 문으로 에러 처리하면 프로그램이 강제 종료되지 않음
```

## Error 객체

Error 객체는 생성자 함수임

Error 생성자 함수가 생성한 에러 객체는 `message 프로퍼티`와 `stack 프로퍼티`를 가짐

> - `message 프로퍼티`는 에러 메시지를 나타내는 문자열이고,
> - `stack 프로퍼티`는 에러 발생 당시의 콜스택을 나타내는 문자열임

| 생성자 함수    | 인스턴스                                                                          |
| -------------- | --------------------------------------------------------------------------------- |
| Error          | 일반적 에러 객체                                                                  |
| SyntaxError    | 문법 에러                                                                         |
| ReferenceError | 참조 에러 (참조할 수 없는 식별자 에러)                                            |
| TypeError      | 타입 에러 (피연산자 또는 인자의 타입이 유효하지 않음)                             |
| RangeError     | 범위 에러 (숫자 범위 초과)                                                        |
| URIError       | URI 에러 (encodeURI, decodeURI, encodeURIComponent, decodeURIComponent 함수 에러) |
| EvalError      | eval 함수 에러                                                                    |

```javascript
1 @ 1; // SyntaxError: Invalid or unexpected token
foo(); // ReferenceError: foo is not defined
null.foo(); // TypeError: Cannot read property 'foo' of null
new Array(-1); // RangeError: Invalid array length
decodeURIComponent('%'); // URIError: URI malformed
eval('a=1'); // EvalError: ReferenceError: Invalid left-hand side in assignment
```

## throw 문

Error 생성자 함수로 ㅔㅇ러 객체를 생성한다고 에러가 발생하는 것은 아님

??? 에러 객체 생성과 에러 발생은 의미가 다르다

> ### 에러 객체 생성
>
> - 개발자가 직접 에러를 생성하는 것
> - Error 객체를 생성해서 에러 메시지를 설정하고 필요에 따라 stack 프로퍼티를 설정하여 에러 객체를 생성함

> ### 에러 발생
>
> - 프로그램 실행 중 예상치 못한 상황이 발생하여 js 엔진이 에러 객체를 생성하는 것
> - 즉 개발자가 직접 제어할 수 없는 상황에서 발생하고 에러는 try catch 문을 사용하여 처리함

에러를 발생시키려면 try 코드 블록에서 throw 문으로 에러 객체를 던져야 함

```javascript
throw 표현식;

throw new Error("에러 메시지");
```

```javascript
const repeat = (n, f) => {
  if (typeof f !== "function") throw new Error("f is not a function");
  for (let i = 0; i < n; i++) {
    f(i);
  }
};
try {
  repeat(2, 1); // 두번째 인수가 함수가 아니므로 TypeError 발생
} catch (error) {
  console.error(error); // TypeError: f is not a function
}
```

## 에러의 전파

`*` 프로미스 참조

```javascript
const foo = () => {
  throw new Error("foo error"); // 4
};

const bar = () => {
  foo(); // 3
};

const baz = () => {
  bar(); // 2
};
try {
  baz(); // 1
} catch (error) {
  console.error(error); // foo error
}
```

1에서 baz 함수를 호출하면 bar 함수를 호출하고 bar 함수는 foo 함수를 호출하고 foo 함수는 에러를 발생시킴

이때 에러는 호출자 방향으로 전파됨

이를 에러의 전파라고 함

```
foo 에서 에러 발생 근데 전파되서 bar 에서 에러 처리 못하고 baz 에서 에러 처리 못하고 최종적으로 try catch 문에서 에러 처리
```
