# 47장 에러 처리

## 47.1 에러 처리의 필요성

```javascript
// 발생 에러를 방치하여 프로그램이 강제 종료 된다.
// [end]가 콘솔에 찍히지 않음
console.log('[start]');

foo(); // ReferenceError: foo is not defined

console.log('[end]');
```

```javascript
// try ... catch 문으로 에러 처리
console.log('[start]');

try {
  foo();
} catch (error) {
  console.error('[에러 발생]', error);
  // [에러 발생] ReferenceError: foo is not defined
}

// 프로그램이 강제 종료 되지 않음
console.log('[end]'); // [end]
```

```javascript
// 에러가 발생하지 않는 예외적인 상황이 발생할 수도 있다.
// DOM에 button 요소가 존재하지 않을 때 querySelect 메서드는 에러 발생 X / null을 반환
const $button = document.querySelect('button'); // null

$button.classList.add('disabled');
// TypeError: Cannot read property 'classList' of null

// 단축 평가 또는 옵셔널 체이닝 연산자로 null 반환값을 처리할 수 있다.
$button?.classList.add('disabled');


// 인수로 전달된 문자열이 CSS 선택자 문법에 맞지 않으면 에러 발생 O
const $elem = document.querySelect('#1');
// DOMException: Failed to execute 'querySelect' on 'Document' : '#1' is not a valid selector.
```

## 47.2 try ... catch ... finally 문

```javascript
try {
  // 실행할 코드 (에러가 발생할 가능성이 있는 코드)
  foo();
} catch (err) {
  // try 코드 블록에서 에러 발생 시 catch 코드 블록 코드 실행
  // err에는 try 코드 블록에서 발생한 Error 객체 전달
  console.error(err); // ReferenceError: foo is not defined
} finally {
  // 에러 발생과 상관없이 반드시 한 번 실행
  console.log('finally');
}
```

## 47.3 Error 객체

- Error 생성자 함수에는 에러를 상세히 설명하는 에러 메시지를 인수로 전달할 수 있다.

```javascript
const error = new Error('invalid');
```

- Error 생성자 함수가 생성한 에러 객체는 message, stack 프로퍼티를 갖는다.
- message 프로퍼티의 값은 Error 생성자 함수에 인수로 전달한 에러 메시지
- stack 프로퍼티의 값은 에러를 발생시킨 콜 스택의 호출 정보를 나타내는 문자열이며 디버깅 목적으로 사용

| 생성자 함수 | 인스턴스 |
|------|---|
| Error | 일반적 에러 객체 |
| SyntaxError | 자바스크립트 문법에 맞지 않는 문을 해석할 때 발생하는 에러 객체 |
| ReferenceError | 참조할 수 없는 식별자를 참조했을 때 발생하는 에러 객체 |
| TypeError | 피연산자 또는 인수의 데이터 타입이 유효하지 않을 때 발생하는 에러 객체 |
| RangeError | 숫자값의 허용 범위를 벗어났을 때 발생하는 에러 객체 |
| URIError | encodeURI 또는 decodeURI 함수에 부적절한 인수를 전달했을 때 발생하는 에러 객체 |
| EvalError | eval 함수에서 발생하는 에러 객체 |

```javascript
1 @ 1; // SyntaxError: Invalid or unexpected token
foo(); // ReferenceError: foo is not defined
null.foo; // TypeError: Cannot read property 'foo' of null
new Array(-1); // RangeError: Invalid array length
decodeURIComponent('%'); // URIError: URI malformed
```

## 47.4 throw 문

```javascript
try {
  // 에러 객체를 생성할 때 반드시 에러가 발생하지는 않는다.
  // 에러 객체 생성과 에러 발생은 의미가 다르다.
  // 에러 발생을 위해 try 코드 블록에서 throw 문이 필요하다.
  new Error('something wrong');
} catch (error) {
  console.log(error);
}
```

```javascript
try {
  // 에러 객체를 던지면 catch 코드 블록이 실행된다.
  throw new Erro('something wrong');
} catch (error) {
  console.log(error);
}
```

## 47.5 에러의 전파

```javascript
// 에러는 호출자 방향으로 전파된다.
// 콜 스택의 아래 방향(실행 중인 실행 컨텍스트가 푸시되기 직전 푸시된 실행 컨텍스트 방향)으로 전파된다.
const foo = () => {
  throw Error('foo에서 발생한 에러'); // (4)
};

const bar = () => {
  foo(); // (3)
};

const baz = () => {
  bar(); // (2)
};

try {
  baz(); // (1)
} catch (err) {
  console.error(err);
}
```

(1)에서 baz 함수를 호출하면 (2)에서 bar 함수가 호출되고 (3)에서 foo 함수가 호출되고 foo 함수는 (4)에서 에러를 throw한다.
이 때 foo 함수가 throw한 에러는 다음과 같이 호출자에게 전파되어 전역에서 캐치된다.

- throw된 에러를 캐치하지 않으면 호출자 방향으로 전파된다. 이때 throw된 에러를 캐치하여 대응하면 프로그램을 강제 종료하지 않고 코드 실행 흐름을 복구할 수 있다.
- throw된 에러를 캐치하지 않으면 프로그램은 강제 종료된다.

1. 비동기 함수인 setTimeout이나 프로미스 후속 처리 메서드의 콜백 함수는 호출자가 없다.
2. 비동기 함수와 프로미스 후속 처리 메서드의 콜백 함수는 태스크 큐나 마이크로태스크 큐에 일시 저장 -> 콜 스택이 비었을 때 이벤트 루프에 의해 콜 스택으로 푸시되어 실행되다.
3. 이 때 콜 스택에 푸시된 콜백 함수의 실행 컨텍스트는 콜 스택의 가장 하부에 존재하게 된다. 따라서 에러를 전파할 호출자가 존재하지 않는다.

